/user/sbini/anaconda3/envs/dgx1/lib/python3.9/site-packages/telegram/ext/conversationhandler.py:287: UserWarning: If 'per_message=False', 'CallbackQueryHandler' will not be tracked for every message.
  warnings.warn(
__main__ - INFO - 13-07-2023 11:32
utils.callbacks - INFO - Entra: {Francesco, https://t.me/S0nFr4, 189947376, complete: False} - 13-07-2023 11:32:55
utils.callbacks - INFO - Entra: {Mario Pellegrino, https://t.me/masterM4st3r, 1520141330, complete: False} - 13-07-2023 11:33:01
utils.utils - ERROR - Problem with: {'first_name': 'Francesco', 'id': 189947376, 'username': 'S0nFr4', 'language_code': 'it', 'is_bot': False} - 2023-07-13 11:33:53.940802 - [Errno 2] No such file or directory: 'audio_samples/eng/12_0.wav'
Stack (most recent call last):
  File "/user/sbini/anaconda3/envs/dgx1/lib/python3.9/threading.py", line 937, in _bootstrap
    self._bootstrap_inner()
  File "/user/sbini/anaconda3/envs/dgx1/lib/python3.9/threading.py", line 980, in _bootstrap_inner
    self.run()
  File "/user/sbini/anaconda3/envs/dgx1/lib/python3.9/threading.py", line 917, in run
    self._target(*self._args, **self._kwargs)
  File "/user/sbini/anaconda3/envs/dgx1/lib/python3.9/site-packages/telegram/ext/updater.py", line 353, in _thread_wrapper
    target(*args, **kwargs)
  File "/user/sbini/anaconda3/envs/dgx1/lib/python3.9/site-packages/telegram/ext/dispatcher.py", line 485, in start
    self.process_update(update)
  File "/user/sbini/anaconda3/envs/dgx1/lib/python3.9/site-packages/telegram/ext/dispatcher.py", line 567, in process_update
    self.dispatch_error(update, exc)
  File "/user/sbini/anaconda3/envs/dgx1/lib/python3.9/site-packages/telegram/ext/dispatcher.py", line 810, in dispatch_error
    callback(update, context)
utils.utils - ERROR - Problem with: {'first_name': 'Francesco', 'id': 189947376, 'username': 'S0nFr4', 'language_code': 'it', 'is_bot': False} - 2023-07-13 11:33:55.847403 - [Errno 2] No such file or directory: 'audio_samples/eng/1_1.wav'
Stack (most recent call last):
  File "/user/sbini/anaconda3/envs/dgx1/lib/python3.9/threading.py", line 937, in _bootstrap
    self._bootstrap_inner()
  File "/user/sbini/anaconda3/envs/dgx1/lib/python3.9/threading.py", line 980, in _bootstrap_inner
    self.run()
  File "/user/sbini/anaconda3/envs/dgx1/lib/python3.9/threading.py", line 917, in run
    self._target(*self._args, **self._kwargs)
  File "/user/sbini/anaconda3/envs/dgx1/lib/python3.9/site-packages/telegram/ext/updater.py", line 353, in _thread_wrapper
    target(*args, **kwargs)
  File "/user/sbini/anaconda3/envs/dgx1/lib/python3.9/site-packages/telegram/ext/dispatcher.py", line 485, in start
    self.process_update(update)
  File "/user/sbini/anaconda3/envs/dgx1/lib/python3.9/site-packages/telegram/ext/dispatcher.py", line 567, in process_update
    self.dispatch_error(update, exc)
  File "/user/sbini/anaconda3/envs/dgx1/lib/python3.9/site-packages/telegram/ext/dispatcher.py", line 810, in dispatch_error
    callback(update, context)
utils.utils - ERROR - Problem with: {'first_name': 'Francesco', 'id': 189947376, 'username': 'S0nFr4', 'language_code': 'it', 'is_bot': False} - 2023-07-13 11:34:10.194958 - [Errno 2] No such file or directory: 'audio_samples/eng/22_1.wav'
Stack (most recent call last):
  File "/user/sbini/anaconda3/envs/dgx1/lib/python3.9/threading.py", line 937, in _bootstrap
    self._bootstrap_inner()
  File "/user/sbini/anaconda3/envs/dgx1/lib/python3.9/threading.py", line 980, in _bootstrap_inner
    self.run()
  File "/user/sbini/anaconda3/envs/dgx1/lib/python3.9/threading.py", line 917, in run
    self._target(*self._args, **self._kwargs)
  File "/user/sbini/anaconda3/envs/dgx1/lib/python3.9/site-packages/telegram/ext/updater.py", line 353, in _thread_wrapper
    target(*args, **kwargs)
  File "/user/sbini/anaconda3/envs/dgx1/lib/python3.9/site-packages/telegram/ext/dispatcher.py", line 485, in start
    self.process_update(update)
  File "/user/sbini/anaconda3/envs/dgx1/lib/python3.9/site-packages/telegram/ext/dispatcher.py", line 567, in process_update
    self.dispatch_error(update, exc)
  File "/user/sbini/anaconda3/envs/dgx1/lib/python3.9/site-packages/telegram/ext/dispatcher.py", line 810, in dispatch_error
    callback(update, context)
utils.utils - ERROR - Problem with: {'first_name': 'Francesco', 'id': 189947376, 'username': 'S0nFr4', 'language_code': 'it', 'is_bot': False} - 2023-07-13 11:34:11.546154 - [Errno 2] No such file or directory: 'audio_samples/eng/10_0.wav'
Stack (most recent call last):
  File "/user/sbini/anaconda3/envs/dgx1/lib/python3.9/threading.py", line 937, in _bootstrap
    self._bootstrap_inner()
  File "/user/sbini/anaconda3/envs/dgx1/lib/python3.9/threading.py", line 980, in _bootstrap_inner
    self.run()
  File "/user/sbini/anaconda3/envs/dgx1/lib/python3.9/threading.py", line 917, in run
    self._target(*self._args, **self._kwargs)
  File "/user/sbini/anaconda3/envs/dgx1/lib/python3.9/site-packages/telegram/ext/updater.py", line 353, in _thread_wrapper
    target(*args, **kwargs)
  File "/user/sbini/anaconda3/envs/dgx1/lib/python3.9/site-packages/telegram/ext/dispatcher.py", line 485, in start
    self.process_update(update)
  File "/user/sbini/anaconda3/envs/dgx1/lib/python3.9/site-packages/telegram/ext/dispatcher.py", line 567, in process_update
    self.dispatch_error(update, exc)
  File "/user/sbini/anaconda3/envs/dgx1/lib/python3.9/site-packages/telegram/ext/dispatcher.py", line 810, in dispatch_error
    callback(update, context)
utils.callbacks - INFO - Entra: {Alejandro Suarez, None, 971441735, complete: False} - 13-07-2023 13:46:50
utils.utils - ERROR - Problem with: {'first_name': 'Alejandro', 'id': 971441735, 'language_code': 'es', 'is_bot': False, 'last_name': 'Suarez'} - 2023-07-13 13:50:02.470966 - [Errno 2] No such file or directory: 'audio_samples/eng/15_5.wav'
Stack (most recent call last):
  File "/user/sbini/anaconda3/envs/dgx1/lib/python3.9/threading.py", line 937, in _bootstrap
    self._bootstrap_inner()
  File "/user/sbini/anaconda3/envs/dgx1/lib/python3.9/threading.py", line 980, in _bootstrap_inner
    self.run()
  File "/user/sbini/anaconda3/envs/dgx1/lib/python3.9/threading.py", line 917, in run
    self._target(*self._args, **self._kwargs)
  File "/user/sbini/anaconda3/envs/dgx1/lib/python3.9/site-packages/telegram/ext/updater.py", line 353, in _thread_wrapper
    target(*args, **kwargs)
  File "/user/sbini/anaconda3/envs/dgx1/lib/python3.9/site-packages/telegram/ext/dispatcher.py", line 485, in start
    self.process_update(update)
  File "/user/sbini/anaconda3/envs/dgx1/lib/python3.9/site-packages/telegram/ext/dispatcher.py", line 567, in process_update
    self.dispatch_error(update, exc)
  File "/user/sbini/anaconda3/envs/dgx1/lib/python3.9/site-packages/telegram/ext/dispatcher.py", line 810, in dispatch_error
    callback(update, context)
utils.utils - ERROR - Problem with: {'first_name': 'Alejandro', 'id': 971441735, 'language_code': 'es', 'is_bot': False, 'last_name': 'Suarez'} - 2023-07-13 13:50:07.198607 - [Errno 2] No such file or directory: 'audio_samples/eng/3_5.wav'
Stack (most recent call last):
  File "/user/sbini/anaconda3/envs/dgx1/lib/python3.9/threading.py", line 937, in _bootstrap
    self._bootstrap_inner()
  File "/user/sbini/anaconda3/envs/dgx1/lib/python3.9/threading.py", line 980, in _bootstrap_inner
    self.run()
  File "/user/sbini/anaconda3/envs/dgx1/lib/python3.9/threading.py", line 917, in run
    self._target(*self._args, **self._kwargs)
  File "/user/sbini/anaconda3/envs/dgx1/lib/python3.9/site-packages/telegram/ext/updater.py", line 353, in _thread_wrapper
    target(*args, **kwargs)
  File "/user/sbini/anaconda3/envs/dgx1/lib/python3.9/site-packages/telegram/ext/dispatcher.py", line 485, in start
    self.process_update(update)
  File "/user/sbini/anaconda3/envs/dgx1/lib/python3.9/site-packages/telegram/ext/dispatcher.py", line 567, in process_update
    self.dispatch_error(update, exc)
  File "/user/sbini/anaconda3/envs/dgx1/lib/python3.9/site-packages/telegram/ext/dispatcher.py", line 810, in dispatch_error
    callback(update, context)
utils.utils - ERROR - Problem with: {'first_name': 'Alejandro', 'id': 971441735, 'language_code': 'es', 'is_bot': False, 'last_name': 'Suarez'} - 2023-07-13 13:50:21.847579 - [Errno 2] No such file or directory: 'audio_samples/eng/17_0.wav'
Stack (most recent call last):
  File "/user/sbini/anaconda3/envs/dgx1/lib/python3.9/threading.py", line 937, in _bootstrap
    self._bootstrap_inner()
  File "/user/sbini/anaconda3/envs/dgx1/lib/python3.9/threading.py", line 980, in _bootstrap_inner
    self.run()
  File "/user/sbini/anaconda3/envs/dgx1/lib/python3.9/threading.py", line 917, in run
    self._target(*self._args, **self._kwargs)
  File "/user/sbini/anaconda3/envs/dgx1/lib/python3.9/site-packages/telegram/ext/updater.py", line 353, in _thread_wrapper
    target(*args, **kwargs)
  File "/user/sbini/anaconda3/envs/dgx1/lib/python3.9/site-packages/telegram/ext/dispatcher.py", line 485, in start
    self.process_update(update)
  File "/user/sbini/anaconda3/envs/dgx1/lib/python3.9/site-packages/telegram/ext/dispatcher.py", line 567, in process_update
    self.dispatch_error(update, exc)
  File "/user/sbini/anaconda3/envs/dgx1/lib/python3.9/site-packages/telegram/ext/dispatcher.py", line 810, in dispatch_error
    callback(update, context)
utils.utils - ERROR - Problem with: {'first_name': 'Alejandro', 'id': 971441735, 'language_code': 'es', 'is_bot': False, 'last_name': 'Suarez'} - 2023-07-13 13:50:34.016909 - [Errno 2] No such file or directory: 'audio_samples/eng/18_0.wav'
Stack (most recent call last):
  File "/user/sbini/anaconda3/envs/dgx1/lib/python3.9/threading.py", line 937, in _bootstrap
    self._bootstrap_inner()
  File "/user/sbini/anaconda3/envs/dgx1/lib/python3.9/threading.py", line 980, in _bootstrap_inner
    self.run()
  File "/user/sbini/anaconda3/envs/dgx1/lib/python3.9/threading.py", line 917, in run
    self._target(*self._args, **self._kwargs)
  File "/user/sbini/anaconda3/envs/dgx1/lib/python3.9/site-packages/telegram/ext/updater.py", line 353, in _thread_wrapper
    target(*args, **kwargs)
  File "/user/sbini/anaconda3/envs/dgx1/lib/python3.9/site-packages/telegram/ext/dispatcher.py", line 485, in start
    self.process_update(update)
  File "/user/sbini/anaconda3/envs/dgx1/lib/python3.9/site-packages/telegram/ext/dispatcher.py", line 567, in process_update
    self.dispatch_error(update, exc)
  File "/user/sbini/anaconda3/envs/dgx1/lib/python3.9/site-packages/telegram/ext/dispatcher.py", line 810, in dispatch_error
    callback(update, context)
utils.utils - ERROR - Problem with: {'first_name': 'Alejandro', 'id': 971441735, 'language_code': 'es', 'is_bot': False, 'last_name': 'Suarez'} - 2023-07-13 13:51:16.921271 - [Errno 2] No such file or directory: 'audio_samples/eng/2_0.wav'
Stack (most recent call last):
  File "/user/sbini/anaconda3/envs/dgx1/lib/python3.9/threading.py", line 937, in _bootstrap
    self._bootstrap_inner()
  File "/user/sbini/anaconda3/envs/dgx1/lib/python3.9/threading.py", line 980, in _bootstrap_inner
    self.run()
  File "/user/sbini/anaconda3/envs/dgx1/lib/python3.9/threading.py", line 917, in run
    self._target(*self._args, **self._kwargs)
  File "/user/sbini/anaconda3/envs/dgx1/lib/python3.9/site-packages/telegram/ext/updater.py", line 353, in _thread_wrapper
    target(*args, **kwargs)
  File "/user/sbini/anaconda3/envs/dgx1/lib/python3.9/site-packages/telegram/ext/dispatcher.py", line 485, in start
    self.process_update(update)
  File "/user/sbini/anaconda3/envs/dgx1/lib/python3.9/site-packages/telegram/ext/dispatcher.py", line 567, in process_update
    self.dispatch_error(update, exc)
  File "/user/sbini/anaconda3/envs/dgx1/lib/python3.9/site-packages/telegram/ext/dispatcher.py", line 810, in dispatch_error
    callback(update, context)
utils.utils - ERROR - Problem with: {'first_name': 'Alejandro', 'id': 971441735, 'language_code': 'es', 'is_bot': False, 'last_name': 'Suarez'} - 2023-07-13 13:51:18.095730 - [Errno 2] No such file or directory: 'audio_samples/eng/21_0.wav'
Stack (most recent call last):
  File "/user/sbini/anaconda3/envs/dgx1/lib/python3.9/threading.py", line 937, in _bootstrap
    self._bootstrap_inner()
  File "/user/sbini/anaconda3/envs/dgx1/lib/python3.9/threading.py", line 980, in _bootstrap_inner
    self.run()
  File "/user/sbini/anaconda3/envs/dgx1/lib/python3.9/threading.py", line 917, in run
    self._target(*self._args, **self._kwargs)
  File "/user/sbini/anaconda3/envs/dgx1/lib/python3.9/site-packages/telegram/ext/updater.py", line 353, in _thread_wrapper
    target(*args, **kwargs)
  File "/user/sbini/anaconda3/envs/dgx1/lib/python3.9/site-packages/telegram/ext/dispatcher.py", line 485, in start
    self.process_update(update)
  File "/user/sbini/anaconda3/envs/dgx1/lib/python3.9/site-packages/telegram/ext/dispatcher.py", line 567, in process_update
    self.dispatch_error(update, exc)
  File "/user/sbini/anaconda3/envs/dgx1/lib/python3.9/site-packages/telegram/ext/dispatcher.py", line 810, in dispatch_error
    callback(update, context)
utils.utils - ERROR - Problem with: {'first_name': 'Alejandro', 'id': 971441735, 'language_code': 'es', 'is_bot': False, 'last_name': 'Suarez'} - 2023-07-13 13:51:18.284170 - [Errno 2] No such file or directory: 'audio_samples/eng/20_1.wav'
Stack (most recent call last):
  File "/user/sbini/anaconda3/envs/dgx1/lib/python3.9/threading.py", line 937, in _bootstrap
    self._bootstrap_inner()
  File "/user/sbini/anaconda3/envs/dgx1/lib/python3.9/threading.py", line 980, in _bootstrap_inner
    self.run()
  File "/user/sbini/anaconda3/envs/dgx1/lib/python3.9/threading.py", line 917, in run
    self._target(*self._args, **self._kwargs)
  File "/user/sbini/anaconda3/envs/dgx1/lib/python3.9/site-packages/telegram/ext/updater.py", line 353, in _thread_wrapper
    target(*args, **kwargs)
  File "/user/sbini/anaconda3/envs/dgx1/lib/python3.9/site-packages/telegram/ext/dispatcher.py", line 485, in start
    self.process_update(update)
  File "/user/sbini/anaconda3/envs/dgx1/lib/python3.9/site-packages/telegram/ext/dispatcher.py", line 567, in process_update
    self.dispatch_error(update, exc)
  File "/user/sbini/anaconda3/envs/dgx1/lib/python3.9/site-packages/telegram/ext/dispatcher.py", line 810, in dispatch_error
    callback(update, context)
utils.utils - ERROR - Problem with: {'first_name': 'Alejandro', 'id': 971441735, 'language_code': 'es', 'is_bot': False, 'last_name': 'Suarez'} - 2023-07-13 13:51:18.535013 - [Errno 2] No such file or directory: 'audio_samples/eng/9_3.wav'
Stack (most recent call last):
  File "/user/sbini/anaconda3/envs/dgx1/lib/python3.9/threading.py", line 937, in _bootstrap
    self._bootstrap_inner()
  File "/user/sbini/anaconda3/envs/dgx1/lib/python3.9/threading.py", line 980, in _bootstrap_inner
    self.run()
  File "/user/sbini/anaconda3/envs/dgx1/lib/python3.9/threading.py", line 917, in run
    self._target(*self._args, **self._kwargs)
  File "/user/sbini/anaconda3/envs/dgx1/lib/python3.9/site-packages/telegram/ext/updater.py", line 353, in _thread_wrapper
    target(*args, **kwargs)
  File "/user/sbini/anaconda3/envs/dgx1/lib/python3.9/site-packages/telegram/ext/dispatcher.py", line 485, in start
    self.process_update(update)
  File "/user/sbini/anaconda3/envs/dgx1/lib/python3.9/site-packages/telegram/ext/dispatcher.py", line 567, in process_update
    self.dispatch_error(update, exc)
  File "/user/sbini/anaconda3/envs/dgx1/lib/python3.9/site-packages/telegram/ext/dispatcher.py", line 810, in dispatch_error
    callback(update, context)
utils.utils - ERROR - Problem with: {'first_name': 'Alejandro', 'id': 971441735, 'language_code': 'es', 'is_bot': False, 'last_name': 'Suarez'} - 2023-07-13 13:51:19.411884 - [Errno 2] No such file or directory: 'audio_samples/eng/13_0.wav'
Stack (most recent call last):
  File "/user/sbini/anaconda3/envs/dgx1/lib/python3.9/threading.py", line 937, in _bootstrap
    self._bootstrap_inner()
  File "/user/sbini/anaconda3/envs/dgx1/lib/python3.9/threading.py", line 980, in _bootstrap_inner
    self.run()
  File "/user/sbini/anaconda3/envs/dgx1/lib/python3.9/threading.py", line 917, in run
    self._target(*self._args, **self._kwargs)
  File "/user/sbini/anaconda3/envs/dgx1/lib/python3.9/site-packages/telegram/ext/updater.py", line 353, in _thread_wrapper
    target(*args, **kwargs)
  File "/user/sbini/anaconda3/envs/dgx1/lib/python3.9/site-packages/telegram/ext/dispatcher.py", line 485, in start
    self.process_update(update)
  File "/user/sbini/anaconda3/envs/dgx1/lib/python3.9/site-packages/telegram/ext/dispatcher.py", line 567, in process_update
    self.dispatch_error(update, exc)
  File "/user/sbini/anaconda3/envs/dgx1/lib/python3.9/site-packages/telegram/ext/dispatcher.py", line 810, in dispatch_error
    callback(update, context)
utils.utils - ERROR - Problem with: {'first_name': 'Alejandro', 'id': 971441735, 'language_code': 'es', 'is_bot': False, 'last_name': 'Suarez'} - 2023-07-13 13:51:31.261272 - [Errno 2] No such file or directory: 'audio_samples/eng/10_0.wav'
Stack (most recent call last):
  File "/user/sbini/anaconda3/envs/dgx1/lib/python3.9/threading.py", line 937, in _bootstrap
    self._bootstrap_inner()
  File "/user/sbini/anaconda3/envs/dgx1/lib/python3.9/threading.py", line 980, in _bootstrap_inner
    self.run()
  File "/user/sbini/anaconda3/envs/dgx1/lib/python3.9/threading.py", line 917, in run
    self._target(*self._args, **self._kwargs)
  File "/user/sbini/anaconda3/envs/dgx1/lib/python3.9/site-packages/telegram/ext/updater.py", line 353, in _thread_wrapper
    target(*args, **kwargs)
  File "/user/sbini/anaconda3/envs/dgx1/lib/python3.9/site-packages/telegram/ext/dispatcher.py", line 485, in start
    self.process_update(update)
  File "/user/sbini/anaconda3/envs/dgx1/lib/python3.9/site-packages/telegram/ext/dispatcher.py", line 567, in process_update
    self.dispatch_error(update, exc)
  File "/user/sbini/anaconda3/envs/dgx1/lib/python3.9/site-packages/telegram/ext/dispatcher.py", line 810, in dispatch_error
    callback(update, context)
utils.utils - ERROR - Problem with: {'first_name': 'Alejandro', 'id': 971441735, 'language_code': 'es', 'is_bot': False, 'last_name': 'Suarez'} - 2023-07-13 13:51:34.144523 - [Errno 2] No such file or directory: 'audio_samples/eng/17_1.wav'
Stack (most recent call last):
  File "/user/sbini/anaconda3/envs/dgx1/lib/python3.9/threading.py", line 937, in _bootstrap
    self._bootstrap_inner()
  File "/user/sbini/anaconda3/envs/dgx1/lib/python3.9/threading.py", line 980, in _bootstrap_inner
    self.run()
  File "/user/sbini/anaconda3/envs/dgx1/lib/python3.9/threading.py", line 917, in run
    self._target(*self._args, **self._kwargs)
  File "/user/sbini/anaconda3/envs/dgx1/lib/python3.9/site-packages/telegram/ext/updater.py", line 353, in _thread_wrapper
    target(*args, **kwargs)
  File "/user/sbini/anaconda3/envs/dgx1/lib/python3.9/site-packages/telegram/ext/dispatcher.py", line 485, in start
    self.process_update(update)
  File "/user/sbini/anaconda3/envs/dgx1/lib/python3.9/site-packages/telegram/ext/dispatcher.py", line 567, in process_update
    self.dispatch_error(update, exc)
  File "/user/sbini/anaconda3/envs/dgx1/lib/python3.9/site-packages/telegram/ext/dispatcher.py", line 810, in dispatch_error
    callback(update, context)
utils.utils - ERROR - Problem with: {'first_name': 'Alejandro', 'id': 971441735, 'language_code': 'es', 'is_bot': False, 'last_name': 'Suarez'} - 2023-07-13 13:51:34.366615 - [Errno 2] No such file or directory: 'audio_samples/eng/19_0.wav'
Stack (most recent call last):
  File "/user/sbini/anaconda3/envs/dgx1/lib/python3.9/threading.py", line 937, in _bootstrap
    self._bootstrap_inner()
  File "/user/sbini/anaconda3/envs/dgx1/lib/python3.9/threading.py", line 980, in _bootstrap_inner
    self.run()
  File "/user/sbini/anaconda3/envs/dgx1/lib/python3.9/threading.py", line 917, in run
    self._target(*self._args, **self._kwargs)
  File "/user/sbini/anaconda3/envs/dgx1/lib/python3.9/site-packages/telegram/ext/updater.py", line 353, in _thread_wrapper
    target(*args, **kwargs)
  File "/user/sbini/anaconda3/envs/dgx1/lib/python3.9/site-packages/telegram/ext/dispatcher.py", line 485, in start
    self.process_update(update)
  File "/user/sbini/anaconda3/envs/dgx1/lib/python3.9/site-packages/telegram/ext/dispatcher.py", line 567, in process_update
    self.dispatch_error(update, exc)
  File "/user/sbini/anaconda3/envs/dgx1/lib/python3.9/site-packages/telegram/ext/dispatcher.py", line 810, in dispatch_error
    callback(update, context)
utils.utils - ERROR - Problem with: {'first_name': 'Alejandro', 'id': 971441735, 'language_code': 'es', 'is_bot': False, 'last_name': 'Suarez'} - 2023-07-13 13:51:34.590925 - [Errno 2] No such file or directory: 'audio_samples/eng/15_2.wav'
Stack (most recent call last):
  File "/user/sbini/anaconda3/envs/dgx1/lib/python3.9/threading.py", line 937, in _bootstrap
    self._bootstrap_inner()
  File "/user/sbini/anaconda3/envs/dgx1/lib/python3.9/threading.py", line 980, in _bootstrap_inner
    self.run()
  File "/user/sbini/anaconda3/envs/dgx1/lib/python3.9/threading.py", line 917, in run
    self._target(*self._args, **self._kwargs)
  File "/user/sbini/anaconda3/envs/dgx1/lib/python3.9/site-packages/telegram/ext/updater.py", line 353, in _thread_wrapper
    target(*args, **kwargs)
  File "/user/sbini/anaconda3/envs/dgx1/lib/python3.9/site-packages/telegram/ext/dispatcher.py", line 485, in start
    self.process_update(update)
  File "/user/sbini/anaconda3/envs/dgx1/lib/python3.9/site-packages/telegram/ext/dispatcher.py", line 567, in process_update
    self.dispatch_error(update, exc)
  File "/user/sbini/anaconda3/envs/dgx1/lib/python3.9/site-packages/telegram/ext/dispatcher.py", line 810, in dispatch_error
    callback(update, context)
utils.utils - ERROR - Problem with: {'first_name': 'Alejandro', 'id': 971441735, 'language_code': 'es', 'is_bot': False, 'last_name': 'Suarez'} - 2023-07-13 13:51:34.847600 - [Errno 2] No such file or directory: 'audio_samples/eng/14_1.wav'
Stack (most recent call last):
  File "/user/sbini/anaconda3/envs/dgx1/lib/python3.9/threading.py", line 937, in _bootstrap
    self._bootstrap_inner()
  File "/user/sbini/anaconda3/envs/dgx1/lib/python3.9/threading.py", line 980, in _bootstrap_inner
    self.run()
  File "/user/sbini/anaconda3/envs/dgx1/lib/python3.9/threading.py", line 917, in run
    self._target(*self._args, **self._kwargs)
  File "/user/sbini/anaconda3/envs/dgx1/lib/python3.9/site-packages/telegram/ext/updater.py", line 353, in _thread_wrapper
    target(*args, **kwargs)
  File "/user/sbini/anaconda3/envs/dgx1/lib/python3.9/site-packages/telegram/ext/dispatcher.py", line 485, in start
    self.process_update(update)
  File "/user/sbini/anaconda3/envs/dgx1/lib/python3.9/site-packages/telegram/ext/dispatcher.py", line 567, in process_update
    self.dispatch_error(update, exc)
  File "/user/sbini/anaconda3/envs/dgx1/lib/python3.9/site-packages/telegram/ext/dispatcher.py", line 810, in dispatch_error
    callback(update, context)
utils.utils - ERROR - Problem with: {'first_name': 'Alejandro', 'id': 971441735, 'language_code': 'es', 'is_bot': False, 'last_name': 'Suarez'} - 2023-07-13 13:51:35.257330 - [Errno 2] No such file or directory: 'audio_samples/eng/17_1.wav'
Stack (most recent call last):
  File "/user/sbini/anaconda3/envs/dgx1/lib/python3.9/threading.py", line 937, in _bootstrap
    self._bootstrap_inner()
  File "/user/sbini/anaconda3/envs/dgx1/lib/python3.9/threading.py", line 980, in _bootstrap_inner
    self.run()
  File "/user/sbini/anaconda3/envs/dgx1/lib/python3.9/threading.py", line 917, in run
    self._target(*self._args, **self._kwargs)
  File "/user/sbini/anaconda3/envs/dgx1/lib/python3.9/site-packages/telegram/ext/updater.py", line 353, in _thread_wrapper
    target(*args, **kwargs)
  File "/user/sbini/anaconda3/envs/dgx1/lib/python3.9/site-packages/telegram/ext/dispatcher.py", line 485, in start
    self.process_update(update)
  File "/user/sbini/anaconda3/envs/dgx1/lib/python3.9/site-packages/telegram/ext/dispatcher.py", line 567, in process_update
    self.dispatch_error(update, exc)
  File "/user/sbini/anaconda3/envs/dgx1/lib/python3.9/site-packages/telegram/ext/dispatcher.py", line 810, in dispatch_error
    callback(update, context)
utils.callbacks - INFO - Entra: {stefano, None, 916811949, complete: False} - 13-07-2023 20:35:11
utils.callbacks - INFO - Entra: {️☁ ɘmɒ oiƹᴎuᴎ, https://t.me/amelolloso, 606936876, complete: False} - 14-07-2023 13:12:43
utils.callbacks - INFO - Entra: {Carolina Settesoldi, https://t.me/Pond97, 529489061, complete: False} - 14-07-2023 13:13:30
utils.callbacks - INFO - Entra: {Alessandra, None, 2038272027, complete: False} - 14-07-2023 14:04:27
utils.callbacks - INFO - Entra: {Vens, https://t.me/vensmlf97, 532045630, complete: False} - 14-07-2023 14:31:57
utils.callbacks - INFO - Entra: {., https://t.me/aldofin, 656214319, complete: False} - 14-07-2023 14:41:52
telegram.ext.updater - ERROR - Error while getting Updates: urllib3 HTTPError ('Connection aborted.', RemoteDisconnected('Remote end closed connection without response'))
utils.utils - ERROR - Problem with: None - 2023-07-14 18:08:52.177323 - urllib3 HTTPError ('Connection aborted.', RemoteDisconnected('Remote end closed connection without response'))
Stack (most recent call last):
  File "/user/sbini/anaconda3/envs/dgx1/lib/python3.9/threading.py", line 937, in _bootstrap
    self._bootstrap_inner()
  File "/user/sbini/anaconda3/envs/dgx1/lib/python3.9/threading.py", line 980, in _bootstrap_inner
    self.run()
  File "/user/sbini/anaconda3/envs/dgx1/lib/python3.9/threading.py", line 917, in run
    self._target(*self._args, **self._kwargs)
  File "/user/sbini/anaconda3/envs/dgx1/lib/python3.9/site-packages/telegram/ext/updater.py", line 353, in _thread_wrapper
    target(*args, **kwargs)
  File "/user/sbini/anaconda3/envs/dgx1/lib/python3.9/site-packages/telegram/ext/dispatcher.py", line 485, in start
    self.process_update(update)
  File "/user/sbini/anaconda3/envs/dgx1/lib/python3.9/site-packages/telegram/ext/dispatcher.py", line 536, in process_update
    self.dispatch_error(None, update)
  File "/user/sbini/anaconda3/envs/dgx1/lib/python3.9/site-packages/telegram/ext/dispatcher.py", line 810, in dispatch_error
    callback(update, context)
telegram.ext.updater - ERROR - Error while getting Updates: urllib3 HTTPError ('Connection aborted.', RemoteDisconnected('Remote end closed connection without response'))
utils.utils - ERROR - Problem with: None - 2023-07-14 18:10:53.830779 - urllib3 HTTPError ('Connection aborted.', RemoteDisconnected('Remote end closed connection without response'))
Stack (most recent call last):
  File "/user/sbini/anaconda3/envs/dgx1/lib/python3.9/threading.py", line 937, in _bootstrap
    self._bootstrap_inner()
  File "/user/sbini/anaconda3/envs/dgx1/lib/python3.9/threading.py", line 980, in _bootstrap_inner
    self.run()
  File "/user/sbini/anaconda3/envs/dgx1/lib/python3.9/threading.py", line 917, in run
    self._target(*self._args, **self._kwargs)
  File "/user/sbini/anaconda3/envs/dgx1/lib/python3.9/site-packages/telegram/ext/updater.py", line 353, in _thread_wrapper
    target(*args, **kwargs)
  File "/user/sbini/anaconda3/envs/dgx1/lib/python3.9/site-packages/telegram/ext/dispatcher.py", line 485, in start
    self.process_update(update)
  File "/user/sbini/anaconda3/envs/dgx1/lib/python3.9/site-packages/telegram/ext/dispatcher.py", line 536, in process_update
    self.dispatch_error(None, update)
  File "/user/sbini/anaconda3/envs/dgx1/lib/python3.9/site-packages/telegram/ext/dispatcher.py", line 810, in dispatch_error
    callback(update, context)
telegram.ext.updater - ERROR - Error while getting Updates: urllib3 HTTPError ('Connection aborted.', RemoteDisconnected('Remote end closed connection without response'))
utils.utils - ERROR - Problem with: None - 2023-07-14 18:43:22.848335 - urllib3 HTTPError ('Connection aborted.', RemoteDisconnected('Remote end closed connection without response'))
Stack (most recent call last):
  File "/user/sbini/anaconda3/envs/dgx1/lib/python3.9/threading.py", line 937, in _bootstrap
    self._bootstrap_inner()
  File "/user/sbini/anaconda3/envs/dgx1/lib/python3.9/threading.py", line 980, in _bootstrap_inner
    self.run()
  File "/user/sbini/anaconda3/envs/dgx1/lib/python3.9/threading.py", line 917, in run
    self._target(*self._args, **self._kwargs)
  File "/user/sbini/anaconda3/envs/dgx1/lib/python3.9/site-packages/telegram/ext/updater.py", line 353, in _thread_wrapper
    target(*args, **kwargs)
  File "/user/sbini/anaconda3/envs/dgx1/lib/python3.9/site-packages/telegram/ext/dispatcher.py", line 485, in start
    self.process_update(update)
  File "/user/sbini/anaconda3/envs/dgx1/lib/python3.9/site-packages/telegram/ext/dispatcher.py", line 536, in process_update
    self.dispatch_error(None, update)
  File "/user/sbini/anaconda3/envs/dgx1/lib/python3.9/site-packages/telegram/ext/dispatcher.py", line 810, in dispatch_error
    callback(update, context)
utils.callbacks - INFO - Entra: {Antonio, https://t.me/Keow01, 747358635, complete: False} - 15-07-2023 08:03:28
utils.callbacks - INFO - Entra: {Cristiana Iadicicco, https://t.me/Crissiiee, 940750610, complete: False} - 15-07-2023 08:13:54
utils.callbacks - INFO - Entra: {Hafsa Taher, None, 5637757826, complete: False} - 15-07-2023 23:39:36
telegram.ext.updater - INFO - Flood control exceeded. Retry in 5.0 seconds
telegram.ext.updater - ERROR - Error while getting Updates: Bad Gateway
utils.utils - ERROR - Problem with: None - 2023-07-16 01:04:24.451110 - Bad Gateway
Stack (most recent call last):
  File "/user/sbini/anaconda3/envs/dgx1/lib/python3.9/threading.py", line 937, in _bootstrap
    self._bootstrap_inner()
  File "/user/sbini/anaconda3/envs/dgx1/lib/python3.9/threading.py", line 980, in _bootstrap_inner
    self.run()
  File "/user/sbini/anaconda3/envs/dgx1/lib/python3.9/threading.py", line 917, in run
    self._target(*self._args, **self._kwargs)
  File "/user/sbini/anaconda3/envs/dgx1/lib/python3.9/site-packages/telegram/ext/updater.py", line 353, in _thread_wrapper
    target(*args, **kwargs)
  File "/user/sbini/anaconda3/envs/dgx1/lib/python3.9/site-packages/telegram/ext/dispatcher.py", line 485, in start
    self.process_update(update)
  File "/user/sbini/anaconda3/envs/dgx1/lib/python3.9/site-packages/telegram/ext/dispatcher.py", line 536, in process_update
    self.dispatch_error(None, update)
  File "/user/sbini/anaconda3/envs/dgx1/lib/python3.9/site-packages/telegram/ext/dispatcher.py", line 810, in dispatch_error
    callback(update, context)
utils.callbacks - INFO - Entra: {Ali Molavi, https://t.me/Molavi19891367, 381078203, complete: False} - 16-07-2023 09:58:06
utils.callbacks - INFO - Entra: {Thomas, None, 6127040556, complete: False} - 16-07-2023 13:25:37
utils.utils - ERROR - Problem with: {'first_name': 'Thomas', 'id': 6127040556, 'language_code': 'es', 'is_bot': False} - 2023-07-16 13:43:25.092583 - Timed out
Stack (most recent call last):
  File "/user/sbini/anaconda3/envs/dgx1/lib/python3.9/threading.py", line 937, in _bootstrap
    self._bootstrap_inner()
  File "/user/sbini/anaconda3/envs/dgx1/lib/python3.9/threading.py", line 980, in _bootstrap_inner
    self.run()
  File "/user/sbini/anaconda3/envs/dgx1/lib/python3.9/threading.py", line 917, in run
    self._target(*self._args, **self._kwargs)
  File "/user/sbini/anaconda3/envs/dgx1/lib/python3.9/site-packages/telegram/ext/updater.py", line 353, in _thread_wrapper
    target(*args, **kwargs)
  File "/user/sbini/anaconda3/envs/dgx1/lib/python3.9/site-packages/telegram/ext/dispatcher.py", line 485, in start
    self.process_update(update)
  File "/user/sbini/anaconda3/envs/dgx1/lib/python3.9/site-packages/telegram/ext/dispatcher.py", line 567, in process_update
    self.dispatch_error(update, exc)
  File "/user/sbini/anaconda3/envs/dgx1/lib/python3.9/site-packages/telegram/ext/dispatcher.py", line 810, in dispatch_error
    callback(update, context)
utils.callbacks - INFO - Entra: {Halldor Karason, None, 6394042332, complete: False} - 16-07-2023 19:04:34
telegram.ext.updater - ERROR - Error while getting Updates: urllib3 HTTPError ('Connection aborted.', RemoteDisconnected('Remote end closed connection without response'))
utils.utils - ERROR - Problem with: None - 2023-07-16 21:59:05.403984 - urllib3 HTTPError ('Connection aborted.', RemoteDisconnected('Remote end closed connection without response'))
Stack (most recent call last):
  File "/user/sbini/anaconda3/envs/dgx1/lib/python3.9/threading.py", line 937, in _bootstrap
    self._bootstrap_inner()
  File "/user/sbini/anaconda3/envs/dgx1/lib/python3.9/threading.py", line 980, in _bootstrap_inner
    self.run()
  File "/user/sbini/anaconda3/envs/dgx1/lib/python3.9/threading.py", line 917, in run
    self._target(*self._args, **self._kwargs)
  File "/user/sbini/anaconda3/envs/dgx1/lib/python3.9/site-packages/telegram/ext/updater.py", line 353, in _thread_wrapper
    target(*args, **kwargs)
  File "/user/sbini/anaconda3/envs/dgx1/lib/python3.9/site-packages/telegram/ext/dispatcher.py", line 485, in start
    self.process_update(update)
  File "/user/sbini/anaconda3/envs/dgx1/lib/python3.9/site-packages/telegram/ext/dispatcher.py", line 536, in process_update
    self.dispatch_error(None, update)
  File "/user/sbini/anaconda3/envs/dgx1/lib/python3.9/site-packages/telegram/ext/dispatcher.py", line 810, in dispatch_error
    callback(update, context)
